Workbook
Name Total_Energies_1: _Energies!$A$16:$C$38
Name Total_Energies_2: _Energies!$A$41:$C$75
Name Total_Energies_3: _Energies!$G$38:$I$62
Name Total_Energies_4: _Energies!$G$28:$I$38
Name Total_Energies_5: _Energies!$G$65:$I$99
Name Total_Energies_6: '_B3LYP En'!$A$76:$C$86

Sheet _Energies
A1: Protonation site | C1: /home/sacal5/Mech_monomers/acid_mech/proton_site
A2: Vacuum | G2: In solvent | K2: DID NOT CONVERGE AT HIGHEST LEVEL
A3: Capping O | G3: can't find this source file!! | K3: Data from -mid level | N3: bogus - I said SCRF but forgot to specify which one, (it auto input "allcheck". Likely why the energies are so similar (though weirdly not indenitcal - don’t know excatly what it did there)
A4: ../C2-Hcap_fromcln.out | G4: solvent/cont_s-C2-Hcap_fromcln.out | N4: _s-C2-Hcap_fromcln.out
A5: SCF Done: E(RwB97XD) = | C5: -970.37932 | D5: A.U. after 1 cycles | G5: SCF Done: E(RwB97XD) = | I5: -970.46405 | K5: -970.37378 | L5: A.U. after 1 cycles | N5: SCF Done: E(RwB97XD) = | P5: -970.37932 | Q5: A.U. after 1 cycles
A6: Zero-point correction= | C6: 0.270466 | D6: (Hartree/Particle) | G6: Zero-point correction= | I6: 0.269854 | K6: 0.26816 | L6: (Hartree/Particle) | N6: Zero-point correction= | P6: 0.270474 | Q6: (Hartree/Particle)
A7: Thermal correction to Energy= | C7: 0.288542 | G7: Thermal correction to Energy= | I7: 0.287516 | N7: Thermal correction to Energy= | P7: 0.288549
A8: Thermal correction to Enthalpy= | C8: 0.289486 | G8: Thermal correction to Enthalpy= | I8: 0.28846 | N8: Thermal correction to Enthalpy= | P8: 0.289493
A9: Thermal correction to Gibbs Free Energy= | C9: 0.22362 | G9: Thermal correction to Gibbs Free Energy= | I9: 0.221945 | N9: Thermal correction to Gibbs Free Energy= | P9: 0.223623
A10: Sum of electronic and zero-point Energies= | C10: -970.10886 | G10: Sum of electronic and zero-point Energies= | I10: -970.1942 | N10: Sum of electronic and zero-point Energies= | P10: -970.10885
A11: Sum of electronic and thermal Energies= | C11: -970.09078 | G11: Sum of electronic and thermal Energies= | I11: -970.17654 | N11: Sum of electronic and thermal Energies= | P11: -970.09077
A12: Sum of electronic and thermal Enthalpies= | C12: -970.08984 | G12: Sum of electronic and thermal Enthalpies= | I12: -970.17559 | N12: Sum of electronic and thermal Enthalpies= | P12: -970.08983
A13: Sum of electronic and thermal Free Energies= | C13: -970.1557 | G13: Sum of electronic and thermal Free Energies= | I13: -970.24211 | N13: Sum of electronic and thermal Free Energies= | P13: -970.1557
A15: bridging O
A16: C2H-ON_fromcln.out | G16: solvent/(s-)C2H-ON_fromcln.out
A17: SCF Done: E(RwB97XD) = -970.379307354 | B17: A.U. | C17: after 1 cycles | G17: SCF Done: E(RwB97XD) = -970.464051778 | H17: A.U. | I17: after 1 cycles
A18: Zero-point correction= | C18: 0.270132 | D18: (Hartree/Particle) | G18: Zero-point correction= | I18: 0.269974 | J18: (Hartree/Particle)
A19: Thermal correction to Energy= | C19: 0.288353 | G19: Thermal correction to Energy= | I19: 0.288411
A20: Thermal correction to Enthalpy= | C20: 0.289297 | G20: Thermal correction to Enthalpy= | I20: 0.289356
A21: Thermal correction to Gibbs Free Energy= | C21: 0.2229 | G21: Thermal correction to Gibbs Free Energy= | I21: 0.222567
A22: Sum of electronic and zero-point Energies= | C22: -970.10918 | G22: Sum of electronic and zero-point Energies= | I22: -970.19408
A23: Sum of electronic and thermal Energies= | C23: -970.09096 | G23: Sum of electronic and thermal Energies= | I23: -970.17564
A24: Sum of electronic and thermal Enthalpies= | C24: -970.09001 | G24: Sum of electronic and thermal Enthalpies= | I24: -970.1747
A25: Sum of electronic and thermal Free Energies= | C25: -970.15641 | G25: Sum of electronic and thermal Free Energies= | I25: -970.24149
A27: Terminal O
A28: C2-OH.out | G28: C2-OH.out
G29: SCF Done: E(RwB97XD) = -970.449963212 | H29: A.U. | I29: after 1 cycles
A30: Zero-point correction= | C30: 0.270016 (Hartree/Particle) | G30: Zero-point correction= | I30: 0.269745 (Hartree/Particle)
A31: Thermal correction to Energy= | C31: 0.288225 | G31: Thermal correction to Energy= | I31: 0.288116
A32: Thermal correction to Enthalpy= | C32: 0.289169 | G32: Thermal correction to Enthalpy= | I32: 0.28906
A33: Thermal correction to Gibbs Free Energy= | C33: 0.223529 | G33: Thermal correction to Gibbs Free Energy= | I33: 0.22298
A34: Sum of electronic and zero-point Energies= | C34: -970.09762 | G34: Sum of electronic and zero-point Energies= | I34: -970.18022
A35: Sum of electronic and thermal Energies= | C35: -970.07941 | G35: Sum of electronic and thermal Energies= | I35: -970.16185
A36: Sum of electronic and thermal Enthalpies= | C36: -970.07846 | G36: Sum of electronic and thermal Enthalpies= | I36: -970.1609
A37: Sum of electronic and thermal Free Energies= | C37: -970.1441 | G37: Sum of electronic and thermal Free Energies= | I37: -970.22698
C40: /home/uccajla/ravensave/delta_G_stab
A41: H20.out | G41: H20.out
A42: SCF Done: E(RwB97XD) = -76.4155806705 | B42: A.U. | C42: after 1 cycles | G42: SCF Done: E(RwB97XD) = -76.4229441399 | H42: A.U. | I42: after 1 cycles
A43: Zero-point correction= | C43: 0.021739 (Hartree/Particle) | G43: Zero-point correction= | I43: 0.021586 (Hartree/Particle)
A44: Thermal correction to Energy= | C44: 0.024574 | G44: Thermal correction to Energy= | I44: 0.024421
...

Sheet _B3LYP En
A1: Vacuum | D1: FIX THESE | E1: solvent
A2: from: | D2: All unconverged
A3: /home/c.sacal5/Scratch/Mech_monomers/proton_site
A5: Capping O | H5: UNCONVERGED | J5: from:
A6: B3LYP_C2-Hcap_fromcln.out | D6: cont_cont_B3LYP_s-C2-Hcap_fromcln.out | H6: B3LYP_s-C2-Hcap_fromcln.out | J6: /home/c.sacal5/Scratch/Mech_monomers/proton_site/solvent
A7: SCF Done: E(RB3LYP) | B7: -970.668824653 A.U. after 1 cycles | D7: SCF Done: E(RB3LYP) | E7: -970.754047106 A.U. after 1 cycles | H7: SCF Done: E(RB3LYP) | I7: -970.754093095 A.U. after 1 cycles
A8: Zero-point correction | B8: 0.265572 (Hartree/Particle) | D8: Zero-point correction | E8: 0.263084 (Hartree/Particle) | H8: Zero-point correction | I8: 0.262777 (Hartree/Particle)
A9: Thermal correction to Energy | B9: 0.284198 | D9: Thermal correction to Energy | E9: 0.279951 | H9: Thermal correction to Energy | I9: 0.279853
A10: Thermal correction to Enthalpy | B10: 0.285142 | D10: Thermal correction to Enthalpy | E10: 0.280895 | H10: Thermal correction to Enthalpy | I10: 0.280797
A11: Thermal correction to Gibbs Free Energy | B11: 0.218052 | D11: Thermal correction to Gibbs Free Energy | E11: 0.218276 | H11: Thermal correction to Gibbs Free Energy | I11: 0.215948
A12: Sum of electronic and zero-point Energies | B12: -970.40325 | D12: Sum of electronic and zero-point Energies | E12: -970.49096 | H12: Sum of electronic and zero-point Energies | I12: -970.49132
A13: Sum of electronic and thermal Energies | B13: -970.38463 | D13: Sum of electronic and thermal Energies | E13: -970.4741 | H13: Sum of electronic and thermal Energies | I13: -970.47424
A14: Sum of electronic and thermal Enthalpies | B14: -970.38368 | D14: Sum of electronic and thermal Enthalpies | E14: -970.47315 | H14: Sum of electronic and thermal Enthalpies | I14: -970.4733
A15: Sum of electronic and thermal Free Energies | B15: -970.45077 | D15: Sum of electronic and thermal Free Energies | E15: -970.53577 | H15: Sum of electronic and thermal Free Energies | I15: -970.53814
A17: bridging O
A18: B3LYP_C2H-ON_fromcln.out | D18: B3LYP_s-C2H-ON_fromcln.out | F18: from:
A19: SCF Done: E(RB3LYP) | B19: -970.668824813 A.U. after 1 cycles | D19: SCF Done: E(RB3LYP) | E19: -970.754093127 A.U. after 1 cycles | F19: /home/c.sacal5/Scratch/Mech_monomers/proton_site/solvent
A20: Zero-point correction | B20: 0.265572 (Hartree/Particle) | D20: Zero-point correction | E20: 0.262749 (Hartree/Particle)
A21: Thermal correction to Energy | B21: 0.284199 | D21: Thermal correction to Energy | E21: 0.279823
A22: Thermal correction to Enthalpy | B22: 0.285143 | D22: Thermal correction to Enthalpy | E22: 0.280767
A23: Thermal correction to Gibbs Free Energy | B23: 0.21805 | D23: Thermal correction to Gibbs Free Energy | E23: 0.216259
A24: Sum of electronic and zero-point Energies | B24: -970.40325 | D24: Sum of electronic and zero-point Energies | E24: -970.49134
A25: Sum of electronic and thermal Energies | B25: -970.38463 | D25: Sum of electronic and thermal Energies | E25: -970.47427
A26: Sum of electronic and thermal Enthalpies | B26: -970.38368 | D26: Sum of electronic and thermal Enthalpies | E26: -970.47333
A27: Sum of electronic and thermal Free Energies | B27: -970.45078 | D27: Sum of electronic and thermal Free Energies | E27: -970.53783
A29: Terminal O
A30: cont_B3LYP_C2-OH.out | D30: :q!
A31: SCF Done: E(RB3LYP) | B31: -970.655939672 A.U. after 1 cycles | D31: SCF Done: E(RB3LYP) | E31: -970.737776740 A.U. after 1 cycles
A32: Zero-point correction | B32: 0.265162 (Hartree/Particle) | D32: Zero-point correction | E32: 0.254654 (Hartree/Particle)
A33: Thermal correction to Energy | B33: 0.283865 | D33: Thermal correction to Energy | E33: 0.269704
A34: Thermal correction to Enthalpy | B34: 0.284809 | D34: Thermal correction to Enthalpy | E34: 0.270648
A35: Thermal correction to Gibbs Free Energy | B35: 0.217742 | D35: Thermal correction to Gibbs Free Energy | E35: 0.21082
A36: Sum of electronic and zero-point Energies | B36: -970.39078 | D36: Sum of electronic and zero-point Energies | E36: -970.48312
A37: Sum of electronic and thermal Energies | B37: -970.37207 | D37: Sum of electronic and thermal Energies | E37: -970.46807
A38: Sum of electronic and thermal Enthalpies | B38: -970.37113 | D38: Sum of electronic and thermal Enthalpies | E38: -970.46713
A39: Sum of electronic and thermal Free Energies | B39: -970.4382 | D39: Sum of electronic and thermal Free Energies | E39: -970.52696
A41: B3LYP_C2-OH.out | B41: UNCONVERGED | D41: B3LYP_s-C2-OH.out | E41: UNCONVERGED | F41: from:
A42: SCF Done: E(RB3LYP) | B42: -970.655939453 A.U. after 1 cycles | D42: SCF Done: E(RB3LYP) | E42: -970.737767586 A.U. after 1 cycles | F42: /home/c.sacal5/Scratch/Mech_monomers/proton_site/solvent
A43: Zero-point correction | B43: 0.265171 (Hartree/Particle) | D43: Zero-point correction | E43: 0.255252 (Hartree/Particle)
A44: Thermal correction to Energy | B44: 0.283863 | D44: Thermal correction to Energy | E44: 0.27014
...

Sheet _MP2 En
A1: from: | H1: solvent
A2: /home/c.sacal5/Scratch/Mech_monomers/proton_site
A4: Capping O | B4: UNCONVERGED | H4: UNCONVERGED
A5: freq_MP2_C2-Hcap_fromcln.out
A6: SCF Done: E(RHF) | B6: -965.202180733 A.U. after 1 cycles
A7: Zero-point correction | B7: 0.268228 (Hartree/Particle)
A8: Thermal correction to Energy | B8: 0.286776
A9: Thermal correction to Enthalpy | B9: 0.287721
A10: Thermal correction to Gibbs Free Energy | B10: 0.220882
A11: Sum of electronic and zero-point Energies | B11: -968.26442
A12: Sum of electronic and thermal Energies | B12: -968.24588
A13: Sum of electronic and thermal Enthalpies | B13: -968.24493
A14: Sum of electronic and thermal Free Energies | B14: -968.31177
A18: bridging O
A19: cont_MP2_C2H-ON_fromcln.out | B19: UNCONVERGED | H19: UNCONVERGED
A20: SCF Done: E(RHF) | B20: -965.202163068 A.U. after 1 cycles
A21: Zero-point correction | B21: 0.268224 (Hartree/Particle)
A22: Thermal correction to Energy | B22: 0.286773
A23: Thermal correction to Enthalpy | B23: 0.287717
A24: Thermal correction to Gibbs Free Energy | B24: 0.220875
A25: Sum of electronic and zero-point Energies | B25: -968.26443
A26: Sum of electronic and thermal Energies | B26: -968.24588
A27: Sum of electronic and thermal Enthalpies | B27: -968.24494
A28: Sum of electronic and thermal Free Energies | B28: -968.31178
A31: Terminal O
A32: freq_MP2_C2-OH.out | B32: UNCONVERGED | G32: MP2_s-C2-OH.out | H32: UNCONVERGED | J32: cont_freq_MP2_C2-OH.out
A33: SCF Done: E(RHF) | B33: -965.236345168 A.U. after 1 cycles | G33: SCF Done: E(RHF) | H33: -965.321373840 A.U. after 1 cycles | J33: SCF Done: E(RHF) = -965.236341166 A.U. after 1 cycles
A34: Zero-point correction | B34: 0.270516 (Hartree/Particle) | G34: Zero-point correction | H34: 0.263579 (Hartree/Particle) | J34: Zero-point correction= 0.270516 (Hartree/Particle)
A35: Thermal correction to Energy | B35: 0.288716 | G35: Thermal correction to Energy | H35: 0.27835 | J35: Thermal correction to Energy= 0.288716
A36: Thermal correction to Enthalpy | B36: 0.28966 | G36: Thermal correction to Enthalpy | H36: 0.279294 | J36: Thermal correction to Enthalpy= 0.289660
A37: Thermal correction to Gibbs Free Energy | B37: 0.224189 | G37: Thermal correction to Gibbs Free Energy | H37: 0.222213 | J37: Thermal correction to Gibbs Free Energy= 0.224190
A38: Sum of electronic and zero-point Energies | B38: -968.24195 | G38: Sum of electronic and zero-point Energies | H38: -968.3316 | J38: Sum of electronic and zero-point Energies= -968.241955
A39: Sum of electronic and thermal Energies | B39: -968.22375 | G39: Sum of electronic and thermal Energies | H39: -968.31682 | J39: Sum of electronic and thermal Energies= -968.223755
A40: Sum of electronic and thermal Enthalpies | B40: -968.22281 | G40: Sum of electronic and thermal Enthalpies | H40: -968.31588 | J40: Sum of electronic and thermal Enthalpies= -968.222811
A41: Sum of electronic and thermal Free Energies | B41: -968.28828 | G41: Sum of electronic and thermal Free Energies | H41: -968.37296 | J41: Sum of electronic and thermal Free Energies= -968.288281
A43: MP2_H20.out | G43: MP2_s-H20.out | H43: UNCONVERGED | J43: cont_MP2_s-H20.out
A44: SCF Done: E(RHF) | B44: -76.0361041999 A.U. after 1 cycles | G44: SCF Done: E(RHF) | H44: -76.0437094005 A.U. after 1 cycles | J44: SCF Done: E(RHF) = -76.0437259378 A.U. after 1 cycles
A45: Zero-point correction | B45: 0.021615 (Hartree/Particle) | G45: Zero-point correction | H45: 0.021491 (Hartree/Particle) | J45: Zero-point correction= 0.021509 (Hartree/Particle)
A46: Thermal correction to Energy | B46: 0.024451 | G46: Thermal correction to Energy | H46: 0.024326 | J46: Thermal correction to Energy= 0.024344
A47: Thermal correction to Enthalpy | B47: 0.025395 | G47: Thermal correction to Enthalpy | H47: 0.02527 | J47: Thermal correction to Enthalpy= 0.025288
...

Sheet _DeltaG
A1: REDO THESE IN B3LYP if these weren't done in that beforehand | K1: hartree | L1: eV | M1: kJmol-1 | N1: kcalmol-1
A2: Vacuum | P2: Favorable, or spontaneous reactions: | Q2: deltaGo < 0
A3: Free energies | C3: NC | D3: + | E3: H3O+ | F3: -> | G3: NC-H | H3: + | I3: H2O | K3: Delta G | P3: Unfavorable, or non-spontaneous reactions: | Q3: deltaGo > 0
G4: Just NC + water, not protonated
A5: Just C2 | C5: -969.84352 | E5: -76.675348 | G5: -969.84352 | I5: -76.675348 | K5: =(G5+I5)-(C5+E5) -> 0 | L5: =K5*27 -> 0 | M5: =$K5*2600 -> 0 | N5: =$K5*630 -> 0
A6: MP2 | C6: -967.99655
A7: B3LYP | C7: -970.14002 | E7: -76.696949 | I7: -76.436967
A9: Bridging | C9: -969.84352 | E9: -76.675348 | G9: -970.15641 | I9: -76.411471 | K9: =(G9+I9)-(C9+E9) -> -0.049012 | L9: =K9*27 -> -1.323324 | M9: =$K9*2600 -> -127.4312 | N9: =$K9*630 -> -30.87756 | O9: most likely but | P9: (it looks like its trying to go to the capping group) | S9: =G9+I9 -> -1046.5679 | T9: =C9+E9 -> -1046.5189 | U9: =S9-T9 -> -0.049012
A10: MP2 | B10: -967.99655 | C10: -967.99655 | E10: -76.532949 | G10: -968.31178 | I10: -76.276371 | K10: =(G10+I10)-(C10+E10) -> -0.058647 | L10: =K10*27 -> -1.583469 | M10: =$K10*2600 -> -152.4822 | N10: =$K10*630 -> -36.94761
A11: B3LYP | C11: -970.14002 | E11: -76.696949 | G11: -970.45078 | I11: -76.436967 | K11: =(G11+I11)-(C11+E11) -> -0.050772 | L11: =K11*27 -> -1.370844 | M11: =$K11*2600 -> -132.0072 | N11: =$K11*630 -> -31.98636
G12: -968.31177
A13: Terminal | C13: -969.84352 | E13: -76.675348 | G13: -970.1441 | I13: -76.411471 | K13: =(G13+I13)-(C13+E13) -> -0.036707 | L13: =K13*27 -> -0.991089 | M13: =$K13*2600 -> -95.4382 | N13: =$K13*630 -> -23.12541 | O13: least likely
A14: MP2 | C14: -967.99655 | E14: -76.532949 | G14: -968.28828 | I14: -76.276371 | K14: =(G14+I14)-(C14+E14) -> -0.035151 | L14: =K14*27 -> -0.949077 | M14: =$K14*2600 -> -91.3926 | N14: =$K14*630 -> -22.14513
A15: B3LYP | C15: -970.14002 | E15: -76.696949 | G15: -970.4382 | I15: -76.436967 | K15: =(G15+I15)-(C15+E15) -> -0.038195 | L15: =K15*27 -> -1.031265 | M15: =$K15*2600 -> -99.307 | N15: =$K15*630 -> -24.06285
A18: Capping | C18: -969.84352 | E18: -76.675348 | G18: -970.1557 | I18: -76.411471 | K18: =(G18+I18)-(C18+E18) -> -0.048308 | L18: =K18*27 -> -1.304316 | M18: =$K18*2600 -> -125.6008 | N18: =$K18*630 -> -30.43404 | O18: less likely | P18: cont_freq_MP2_C2-Hcap_fromcln.out
A19: MP2 | C19: -967.99655 | E19: -76.532949 | G19: -968.31178 | I19: -76.276371 | K19: =(G19+I19)-(C19+E19) -> -0.058646 | L19: =K19*27 -> -1.583442 | M19: =$K19*2600 -> -152.4796 | N19: =$K19*630 -> -36.94698
A20: B3LYP | C20: -970.14002 | E20: -76.696949 | G20: -970.45077 | I20: -76.436967 | K20: =(G20+I20)-(C20+E20) -> -0.050769 | L20: =K20*27 -> -1.370763 | M20: =$K20*2600 -> -131.9994 | N20: =$K20*630 -> -31.98447
I22: Significant diff between DFT and MP2 waters
B24: NONE OF THESE ARE CONVERGED | K24: unfortunately none were converged…
A25: Solvent
A26: Free energies | C26: NC | D26: + | E26: H3O+ | F26: -> | G26: NC-H | H26: + | I26: H2O | K26: Delta G | O26: IT DOESN'T WANT TO BE PROTONATED IN SOLVENT
O27: But only by a small amount
A28: Just C2 | C28: -969.86328 | E28: -76.798567 | G28: -969.86328 | I28: -76.798567 | K28: =(G28+I28)-(C28+E28) -> 0 | L28: =K28*27 -> 0 | M28: =$K28*2600 -> 0 | N28: =$K28*630 -> 0
A29: MP2 | B29: not con | C29: -968.01475 | D29: freq_cont_MP2_s-C2.out
A30: B3LYP | C30: -970.15772 | E30: -76.824035 | I30: -76.444312
A33: Bridging | C33: -969.86328 | E33: -76.798567 | G33: -970.24149 | I33: -76.418996 | K33: =(G33+I33)-(C33+E33) -> 0.001364 | L33: =K33*27 -> 0.036828 | M33: =$K33*2600 -> 3.5464 | N33: =$K33*630 -> 0.85932 | P33: (it looks like its trying to go to the capping group) | S33: =I33+G33 -> -1046.6605 | T33: =E33+C33 -> -1046.6618 | U33: =S33-T33 -> 0.001364
A34: MP2 | C34: -968.01475 | E34: -76.660998 | G34: -968.40976 | H34: freq_MP2_s-C2H-ON_fromcln.out | I34: -76.284031 | K34: =(G34+I34)-(C34+E34) -> -0.018041 | L34: =K34*27 -> -0.487107 | M34: =$K34*2600 -> -46.9066 | N34: =$K34*630 -> -11.36583 | P34: cont_MP2_s-H3O.out
A35: B3LYP | C35: -970.15772 | E35: -76.824035 | G35: -970.53783 | I35: -76.444312 | K35: =(G35+I35)-(C35+E35) -> -0.000389 | L35: =K35*27 -> -0.010503 | M35: =$K35*2600 -> -1.0114 | N35: =$K35*630 -> -0.24507 | P35: B3LYP_s-C2H-ON_fromcln.out
A37: Terminal | C37: -969.86328 | E37: -76.798567 | G37: -970.22698 | I37: -76.418996 | K37: =(G37+I37)-(C37+E37) -> 0.015866 | L37: =K37*27 -> 0.428382 | M37: =$K37*2600 -> 41.2516 | N37: =$K37*630 -> 9.99558 | O37: not likely
A38: MP2 | C38: -968.01475 | E38: -76.660998 | G38: -968.37296 | H38: freq_MP2_s-C2-Hcap_fromcln.out | I38: -76.284031 | K38: =(G38+I38)-(C38+E38) -> 0.018758 | L38: =K38*27 -> 0.506466 | M38: =$K38*2600 -> 48.7708 | N38: =$K38*630 -> 11.81754
A39: B3LYP | C39: -970.15772 | E39: -76.824035 | G39: -970.52696 | I39: -76.444312 | K39: =(G39+I39)-(C39+E39) -> 0.010488 | L39: =K39*27 -> 0.283176 | M39: =$K39*2600 -> 27.2688 | N39: =$K39*630 -> 6.60744
A41: Capping | C41: -969.86328 | E41: -76.798567 | G41: -970.24211 | I41: -76.418996 | K41: =(G41+I41)-(C41+E41) -> 0.000742 | L41: =K41*27 -> 0.020034 | M41: =$K41*2600 -> 1.9292 | N41: =$K41*630 -> 0.46746 | O41: oooooh most likely
A42: MP2 | C42: -968.01475 | E42: -76.660998 | G42: -968.40957 | I42: -76.284031 | K42: =(G42+I42)-(C42+E42) -> -0.017853 | L42: =K42*27 -> -0.482031 | M42: =$K42*2600 -> -46.4178 | N42: =$K42*630 -> -11.24739
A43: B3LYP | C43: -970.15772 | E43: -76.824035 | G43: -970.53814 | I43: -76.444312 | K43: =(G43+I43)-(C43+E43) -> -0.0007 | L43: =K43*27 -> -0.0189 | M43: =$K43*2600 -> -1.82 | N43: =$K43*630 -> -0.441 | P43: B3LYP_s-C2-Hcap_fromcln.out
G44: -970.53577 | O44: Though be skeptical - you only managed to optimise this later and WITHOUT the zmat part.
G45: -970.1557 | I45: bogus - I said SCRF but forgot to specify which one, in the first opt | O45: Trying again with that switched on to see whether the energy is sginifciantly different or not
E48: YOU GOT THESE MIXED UP
B50: Protonation Site | C50: (Protonation reaction) | K50: ΔG of protonation
B51: Protonation Site | C51: NC | D51: + | E51: H3O+ | F51: -> | G51: NC-H | H51: + | I51: H2O | K51: H | L51: eV | M51: kJ/mol | N51: kCal/mol
A52: Vac | B52: Bridging | C52: -969.84352 | E52: -76.675348 | G52: -970.15641 | I52: -76.411471 | K52: =(I52+G52)-(E52+C52) -> -0.049012 | L52: =K52*27 -> -1.323324 | M52: =$K52*2600 -> -127.4312 | N52: =$K52*630 -> -30.87756
...

Sheet DeltaG (2)
A1: REDO THESE IN B3LYP if these weren't done in that beforehand | K1: hartree | L1: eV | M1: kJmol-1 | N1: kcalmol-1
A2: Vacuum | O2: 8.9.2019 | P2: Favorable, or spontaneous reactions: | Q2: deltaGo < 0
A3: Free energies | C3: NC | D3: + | E3: H3O+ | F3: -> | G3: NC-H | H3: + | I3: H2O | K3: Delta G | O3: found out none of my solvent calcs converged. Drama | P3: Unfavorable, or non-spontaneous reactions: | Q3: deltaGo > 0
G4: Just NC + water, not protonated
A5: Just C2 | C5: -969.84352 | E5: -76.675348 | G5: -969.84352 | I5: -76.675348 | K5: =(G5+I5)-(C5+E5) -> 0 | L5: =K5*27 -> 0 | M5: =$K5*2600 -> 0 | N5: =$K5*630 -> 0
A6: MP2 | C6: -967.99655
A7: B3LYP
A9: Bridging | C9: -969.84352 | E9: -76.675348 | G9: -970.15641 | I9: -76.411471 | K9: =(G9+I9)-(C9+E9) -> -0.049012 | L9: =K9*27 -> -1.323324 | M9: =$K9*2600 -> -127.4312 | N9: =$K9*630 -> -30.87756 | O9: most likely but | P9: (it looks like its trying to go to the capping group) | S9: =G9+I9 -> -1046.5679 | T9: =C9+E9 -> -1046.5189 | U9: =S9-T9 -> -0.049012
A10: MP2 | B10: -967.99655 | C10: -968.31178 | E10: -76.532949 | G10: -968.31178 | I10: -76.276371
A11: B3LYP
G12: -968.31177
A13: Terminal | C13: -969.84352 | E13: -76.675348 | G13: -970.1441 | I13: -76.411471 | K13: =(G13+I13)-(C13+E13) -> -0.036707 | L13: =K13*27 -> -0.991089 | M13: =$K13*2600 -> -95.4382 | N13: =$K13*630 -> -23.12541 | O13: least likely
A14: MP2 | C14: -968.28828 | G14: -968.28828
A15: B3LYP
A18: Capping | C18: -969.84352 | E18: -76.675348 | G18: -970.1557 | I18: -76.411471 | K18: =(G18+I18)-(C18+E18) -> -0.048308 | L18: =K18*27 -> -1.304316 | M18: =$K18*2600 -> -125.6008 | N18: =$K18*630 -> -30.43404 | O18: less likely
A19: MP2 | C19: -968.31177 | G19: -968.31177
A20: B3LYP
A25: Solvent
A26: Free energies | C26: NC | D26: + | E26: H3O+ | F26: -> | G26: NC-H | H26: + | I26: H2O | K26: Delta G | O26: IT DOESN'T WANT TO BE PROTONATED IN SOLVENT
O27: But only by a small amount
A28: Just C2 | C28: -969.86328 | E28: -76.798567 | G28: -969.86328 | I28: -76.798567 | K28: =(G28+I28)-(C28+E28) -> 0 | L28: =K28*27 -> 0 | M28: =$K28*2600 -> 0 | N28: =$K28*630 -> 0
A29: MP2
A30: B3LYP
A33: Bridging | C33: -969.86328 | E33: -76.798567 | G33: -970.24149 | I33: -76.418996 | K33: =(G33+I33)-(C33+E33) -> 0.001364 | L33: =K33*27 -> 0.036828 | M33: =$K33*2600 -> 3.5464 | N33: =$K33*630 -> 0.85932 | P33: (it looks like its trying to go to the capping group) | S33: =I33+G33 -> -1046.6605 | T33: =E33+C33 -> -1046.6618 | U33: =S33-T33 -> 0.001364
A34: smd
A35: MP2
A36: smd
A37: B3LYP
A38: smd
A40: Terminal | C40: -969.86328 | E40: -76.798567 | G40: -970.22698 | I40: -76.418996 | K40: =(G40+I40)-(C40+E40) -> 0.015866 | L40: =K40*27 -> 0.428382 | M40: =$K40*2600 -> 41.2516 | N40: =$K40*630 -> 9.99558 | O40: not likely
A41: smd
A42: MP2
A43: smd
A44: B3LYP
A45: smd
A47: Capping | C47: -969.86328 | E47: -76.798567 | G47: -970.24211 | I47: -76.418996 | K47: =(G47+I47)-(C47+E47) -> 0.000742 | L47: =K47*27 -> 0.020034 | M47: =$K47*2600 -> 1.9292 | N47: =$K47*630 -> 0.46746 | O47: oooooh most likely
A48: smd
A49: MP2
A50: smd
A51: B3LYP
...

Sheet For_csv
A1: Protonation Site | B1: ΔG protonation
B2: WB97XD | C2: B3LYP | D2: MP2
A3: Bridging | B3: =_DeltaG!N9 -> -30.87756 | C3: =_DeltaG!N11 -> -31.98636 | D3: =_DeltaG!N10 -> -36.94761
A5: Terminal | B5: =_DeltaG!N13 -> -23.12541 | C5: =_DeltaG!N15 -> -24.06285 | D5: =_DeltaG!N14 -> -22.14513
A7: Capping | B7: =_DeltaG!L18 -> -1.304316 | C7: =_DeltaG!N20 -> -31.98447 | D7: =_DeltaG!N19 -> -36.94698

Sheet CSV_solv
A1: Protonation Site | B1: ΔG protonation
B2: WB97XD | C2: PCM | D2: SMD
A3: Bridging | C3: =_DeltaG!N33 -> 0.85932
A5: Terminal | C5: =_DeltaG!N37 -> 9.99558
A7: Capping | C7: =_DeltaG!N41 -> 0.46746

Sheet Energies
A1: from: | B1: wb97xd / 6-31+g(2df,p)
A2: /home/c.sacal5/Scratch/Mech_monomers/proton_site/corrected
E4: =A5 -> C2_NC3-CH3_corr-C2H-ON.out | F4: =B14 -> -970.15885
A5: C2_NC3-CH3_corr-C2H-ON.out | E5: =A17 -> C2_NC3-CH3_corr-Hcap.out | F5: =B26 -> -970.16489
A6: SCF Done: E(RwB97XD) | B6: -970.379804786 A.U. after 1 cycles | E6: =A29 -> C2_NC3-CH3_corr-OH_down.out | F6: =B38 -> -970.15011
A7: Zero-point correction | B7: 0.268380 (Hartree/Particle) | E7: =A41 -> C2_NC3-CH3_corr-OH_up.out | F7: =B50 -> -970.16489 | G7: FACKKKK This says its more likely to be the terminal one, than the bridging, like I saw before.
A8: Thermal correction to Energy | B8: 0.287522 | E8: =A53 -> C2_NC3-CH3_corr_HI.out | F8: =B62 -> -969.85363
A9: Thermal correction to Enthalpy | B9: 0.288466
A10: Thermal correction to Gibbs Free Energy | B10: 0.220959 | E10: This corresponds to some of the cyclic transition states I looked at but not for the bridging scans.
A11: Sum of electronic and zero-point Energies | B11: -970.11143 | E11: But if you look at the geometry of the briding - the scans totally make sense, because the NO2 looks like it wants to come off anyways.
A12: Sum of electronic and thermal Energies | B12: -970.09228
A13: Sum of electronic and thermal Enthalpies | B13: -970.09134
A14: Sum of electronic and thermal Free Energies | B14: -970.15885
A17: C2_NC3-CH3_corr-Hcap.out
A18: SCF Done: E(RwB97XD) | B18: -970.387602126 A.U. after 1 cycles
A19: Zero-point correction | B19: 0.269354 (Hartree/Particle)
A20: Thermal correction to Energy | B20: 0.287609
A21: Thermal correction to Enthalpy | B21: 0.288553
A22: Thermal correction to Gibbs Free Energy | B22: 0.222712
A23: Sum of electronic and zero-point Energies | B23: -970.11825
A24: Sum of electronic and thermal Energies | B24: -970.09999
A25: Sum of electronic and thermal Enthalpies | B25: -970.09905
A26: Sum of electronic and thermal Free Energies | B26: -970.16489
A29: C2_NC3-CH3_corr-OH_down.out
A30: SCF Done: E(RwB97XD) | B30: -970.372903461 A.U. after 1 cycles
A31: Zero-point correction | B31: 0.269789 (Hartree/Particle)
A32: Thermal correction to Energy | B32: 0.288158
A33: Thermal correction to Enthalpy | B33: 0.289102
A34: Thermal correction to Gibbs Free Energy | B34: 0.222796
A35: Sum of electronic and zero-point Energies | B35: -970.10311
A36: Sum of electronic and thermal Energies | B36: -970.08475
A37: Sum of electronic and thermal Enthalpies | B37: -970.0838
A38: Sum of electronic and thermal Free Energies | B38: -970.15011
A41: C2_NC3-CH3_corr-OH_up.out
A42: SCF Done: E(RwB97XD) | B42: -970.387602117 A.U. after 1 cycles
A43: Zero-point correction | B43: 0.269354 (Hartree/Particle)
A44: Thermal correction to Energy | B44: 0.287609
A45: Thermal correction to Enthalpy | B45: 0.288553
A46: Thermal correction to Gibbs Free Energy | B46: 0.222713
A47: Sum of electronic and zero-point Energies | B47: -970.11825
...

Sheet solv
A1: from:
A2: /home/c.sacal5/Scratch/Mech_monomers/proton_site/corrected/solv
E4: =E16 -> s_C2_NC3-CH3_corr-C2H-ON.out | F4: =F25 -> -970.2415 | H4: smd_C2_NC3-CH3_corr-C2H-ON.out | I4: -970.2555 | J4: Must consider what this means for solvent!!
E5: =E28 -> s_C2_NC3-CH3_corr-Hcap.out | F5: =F37 -> -970.24215 | H5: smd_C2_NC3-CH3_corr-Hcap.out | I5: -970.27236
E6: =E40 -> s_C2_NC3-CH3_corr-OH_down.out | F6: =F49 -> -970.23131 | H6: smd_C2_NC3-CH3_corr-OH_down.out | I6: -970.25294
E7: =E52 -> s_C2_NC3-CH3_corr-OH_up.out | F7: =F61 -> -970.20934 | H7: smd_C2_NC3-CH3_corr-OH_up.out | I7: -970.25086
E8: =E64 -> s_C2_NC3-CH3_corr_HI.out | F8: =F73 -> -969.86832 | H8: smd_C2_NC3-CH3_corr_HI.out | I8: -969.8757
H10: why does SMD give much lower abs energies?
E11: must have given a completely different geometry to the WB97XD vacuum calc - solvent stabilisation doesn't allow H to fly off to the capping group?
E12: More realistic?
E14: Unconverged
E16: s_C2_NC3-CH3_corr-C2H-ON.out
E17: SCF Done: E(RwB97XD) | F17: -970.462948132 A.U. after 1 cycles
E18: Zero-point correction | F18: 0.264769 (Hartree/Particle)
E19: Thermal correction to Energy | F19: 0.28075
E20: Thermal correction to Enthalpy | F20: 0.281694
E21: Thermal correction to Gibbs Free Energy | F21: 0.221452
E22: Sum of electronic and zero-point Energies | F22: -970.19818
E23: Sum of electronic and thermal Energies | F23: -970.1822
E24: Sum of electronic and thermal Enthalpies | F24: -970.18125
E25: Sum of electronic and thermal Free Energies | F25: -970.2415
E28: s_C2_NC3-CH3_corr-Hcap.out
E29: SCF Done: E(RwB97XD) | F29: -970.472890308 A.U. after 1 cycles
E30: Zero-point correction | F30: 0.272976 (Hartree/Particle)
E31: Thermal correction to Energy | F31: 0.287772
E32: Thermal correction to Enthalpy | F32: 0.288716
E33: Thermal correction to Gibbs Free Energy | F33: 0.230742
E34: Sum of electronic and zero-point Energies | F34: -970.19991
E35: Sum of electronic and thermal Energies | F35: -970.18512
E36: Sum of electronic and thermal Enthalpies | F36: -970.18417
E37: Sum of electronic and thermal Free Energies | F37: -970.24215
E40: s_C2_NC3-CH3_corr-OH_down.out
E41: SCF Done: E(RwB97XD) | F41: -970.455369574 A.U. after 1 cycles
E42: Zero-point correction | F42: 0.262707 (Hartree/Particle)
E43: Thermal correction to Energy | F43: 0.274945
E44: Thermal correction to Enthalpy | F44: 0.27589
E45: Thermal correction to Gibbs Free Energy | F45: 0.224056
E46: Sum of electronic and zero-point Energies | F46: -970.19266
E47: Sum of electronic and thermal Energies | F47: -970.18042
E48: Sum of electronic and thermal Enthalpies | F48: -970.17948
...

Sheet B3LYP
A1: from:
A2: /home/c.sacal5/Scratch/Mech_monomers/proton_site/corrected/B3LYP
E4: =A5 -> B3LYP_C2_NC3-CH3_corr-C2H-ON.out | F4: =B14 -> -970.45533
A5: B3LYP_C2_NC3-CH3_corr-C2H-ON.out | E5: =A17 -> B3LYP_C2_NC3-CH3_corr-Hcap.out | F5: =B26 -> -970.45932
A6: SCF Done: E(RB3LYP) | B6: -970.671643993 A.U. after 1 cycles | E6: =A29 -> B3LYP_C2_NC3-CH3_corr-OH_down.out | F6: =B38 -> -970.44538
A7: Zero-point correction | B7: 0.263967 (Hartree/Particle) | E7: =A41 -> B3LYP_C2_NC3-CH3_corr-OH_up.out | F7: =B50 -> -970.45932
A8: Thermal correction to Energy | B8: 0.283331 | E8: =A53 -> B3LYP_C2_NC3-CH3_corr_HI.out | F8: =B62 -> -970.14984
A9: Thermal correction to Enthalpy | B9: 0.284275
A10: Thermal correction to Gibbs Free Energy | B10: 0.216317
A11: Sum of electronic and zero-point Energies | B11: -970.40768
A12: Sum of electronic and thermal Energies | B12: -970.38831
A13: Sum of electronic and thermal Enthalpies | B13: -970.38737
A14: Sum of electronic and thermal Free Energies | B14: -970.45533
A17: B3LYP_C2_NC3-CH3_corr-Hcap.out
A18: SCF Done: E(RB3LYP) | B18: -970.677172426 A.U. after 1 cycles
A19: Zero-point correction | B19: 0.264879 (Hartree/Particle)
A20: Thermal correction to Energy | B20: 0.283471
A21: Thermal correction to Enthalpy | B21: 0.284415
A22: Thermal correction to Gibbs Free Energy | B22: 0.217853
A23: Sum of electronic and zero-point Energies | B23: -970.41229
A24: Sum of electronic and thermal Energies | B24: -970.3937
A25: Sum of electronic and thermal Enthalpies | B25: -970.39276
A26: Sum of electronic and thermal Free Energies | B26: -970.45932
A29: B3LYP_C2_NC3-CH3_corr-OH_down.out
A30: SCF Done: E(RB3LYP) | B30: -970.662511963 A.U. after 1 cycles
A31: Zero-point correction | B31: 0.265253 (Hartree/Particle)
A32: Thermal correction to Energy | B32: 0.284051
A33: Thermal correction to Enthalpy | B33: 0.284995
A34: Thermal correction to Gibbs Free Energy | B34: 0.217129
A35: Sum of electronic and zero-point Energies | B35: -970.39726
A36: Sum of electronic and thermal Energies | B36: -970.37846
A37: Sum of electronic and thermal Enthalpies | B37: -970.37752
A38: Sum of electronic and thermal Free Energies | B38: -970.44538
A41: B3LYP_C2_NC3-CH3_corr-OH_up.out
A42: SCF Done: E(RB3LYP) | B42: -970.677172420 A.U. after 1 cycles
A43: Zero-point correction | B43: 0.264879 (Hartree/Particle)
A44: Thermal correction to Energy | B44: 0.283471
A45: Thermal correction to Enthalpy | B45: 0.284415
A46: Thermal correction to Gibbs Free Energy | B46: 0.217854
A47: Sum of electronic and zero-point Energies | B47: -970.41229
...

Sheet B3_solv
E4: =E15 -> s_B3LYP_C2_NC3-CH3_corr-C2H-ON.out | F4: =F24 -> -970.5259 | G4: Now these two are strangely similar
E5: =E27 -> s_B3LYP_C2_NC3-CH3_corr-Hcap.out | F5: =F36 -> -970.54567
E6: =E39 -> s_B3LYP_C2_NC3-CH3_corr-OH_down.out | F6: =F48 -> -970.52531
E7: =E51 -> s_B3LYP_C2_NC3-CH3_corr-OH_up.out | F7: =F60 -> -970.51949
E8: =E63 -> s_B3LYP_C2_NC3-CH3_corr_HI.out | F8: =F72 -> -970.1641
E11: UNCONVERGED:
E12: /home/c.sacal5/Scratch/Mech_monomers/proton_site/corrected/B3LYP/solv
E15: s_B3LYP_C2_NC3-CH3_corr-C2H-ON.out
E16: SCF Done: E(RB3LYP) | F16: -970.751785219 A.U. after 1 cycles
E17: Zero-point correction | F17: 0.270048 (Hartree/Particle)
E18: Thermal correction to Energy | F18: 0.28674
E19: Thermal correction to Enthalpy | F19: 0.287685
E20: Thermal correction to Gibbs Free Energy | F20: 0.225888
E21: Sum of electronic and zero-point Energies | F21: -970.48174
E22: Sum of electronic and thermal Energies | F22: -970.46505
E23: Sum of electronic and thermal Enthalpies | F23: -970.4641
E24: Sum of electronic and thermal Free Energies | F24: -970.5259
E27: s_B3LYP_C2_NC3-CH3_corr-Hcap.out
E28: SCF Done: E(RB3LYP) | F28: -970.762350295 A.U. after 1 cycles
E29: Zero-point correction | F29: 0.259002 (Hartree/Particle)
E30: Thermal correction to Energy | F30: 0.274442
E31: Thermal correction to Enthalpy | F31: 0.275386
E32: Thermal correction to Gibbs Free Energy | F32: 0.216682
E33: Sum of electronic and zero-point Energies | F33: -970.50335
E34: Sum of electronic and thermal Energies | F34: -970.48791
E35: Sum of electronic and thermal Enthalpies | F35: -970.48696
E36: Sum of electronic and thermal Free Energies | F36: -970.54567
E39: s_B3LYP_C2_NC3-CH3_corr-OH_down.out
E40: SCF Done: E(RB3LYP) | F40: -970.744136716 A.U. after 1 cycles
E41: Zero-point correction | F41: 0.260283 (Hartree/Particle)
E42: Thermal correction to Energy | F42: 0.274256
E43: Thermal correction to Enthalpy | F43: 0.2752
E44: Thermal correction to Gibbs Free Energy | F44: 0.218831
E45: Sum of electronic and zero-point Energies | F45: -970.48385
E46: Sum of electronic and thermal Energies | F46: -970.46988
E47: Sum of electronic and thermal Enthalpies | F47: -970.46894
E48: Sum of electronic and thermal Free Energies | F48: -970.52531
E51: s_B3LYP_C2_NC3-CH3_corr-OH_up.out
E52: SCF Done: E(RB3LYP) | F52: -970.740260131 A.U. after 1 cycles
E53: Zero-point correction | F53: 0.260765 (Hartree/Particle)
...

Sheet MP2
A1: from:
A2: /home/c.sacal5/Scratch/Mech_monomers/proton_site/corrected/MP2
E4: =A5 -> MP2_C2_NC3-CH3_corr-C2H-ON.out | F4: =B14 -> -968.32954
A5: MP2_C2_NC3-CH3_corr-C2H-ON.out | E5: =A17 -> MP2_C2_NC3-CH3_corr-Hcap.out | F5: =B26 -> -968.30763
A6: SCF Done: E(RHF) | B6: -965.238166173 A.U. after 1 cycles | E6: =A29 -> MP2_C2_NC3-CH3_corr-OH_down.out | F6: =B38 -> -968.29197
A7: Zero-point correction | B7: 0.269199 (Hartree/Particle) | E7: =A41 -> MP2_C2_NC3-CH3_corr-OH_up.out | F7: =B50 -> -968.30763
A8: Thermal correction to Energy | B8: 0.288461 | E8: =A53 -> MP2_C2_NC3-CH3_corr_HI.out | F8: =B62 -> -968.00523
A9: Thermal correction to Enthalpy | B9: 0.289405
A10: Thermal correction to Gibbs Free Energy | B10: 0.221637
A11: Sum of electronic and zero-point Energies | B11: -968.28198
A12: Sum of electronic and thermal Energies | B12: -968.26272
A13: Sum of electronic and thermal Enthalpies | B13: -968.26178
A14: Sum of electronic and thermal Free Energies | B14: -968.32954
A17: MP2_C2_NC3-CH3_corr-Hcap.out
A18: SCF Done: E(RHF) | B18: -965.251333771 A.U. after 1 cycles
A19: Zero-point correction | B19: 0.269959 (Hartree/Particle)
A20: Thermal correction to Energy | B20: 0.288232
A21: Thermal correction to Enthalpy | B21: 0.289176
A22: Thermal correction to Gibbs Free Energy | B22: 0.223441
A23: Sum of electronic and zero-point Energies | B23: -968.26111
A24: Sum of electronic and thermal Energies | B24: -968.24284
A25: Sum of electronic and thermal Enthalpies | B25: -968.24189
A26: Sum of electronic and thermal Free Energies | B26: -968.30763
A29: MP2_C2_NC3-CH3_corr-OH_down.out
A30: SCF Done: E(RHF) | B30: -965.243021575 A.U. after 1 cycles
A31: Zero-point correction | B31: 0.270430 (Hartree/Particle)
A32: Thermal correction to Energy | B32: 0.288753
A33: Thermal correction to Enthalpy | B33: 0.289697
A34: Thermal correction to Gibbs Free Energy | B34: 0.223838
A35: Sum of electronic and zero-point Energies | B35: -968.24538
A36: Sum of electronic and thermal Energies | B36: -968.22705
A37: Sum of electronic and thermal Enthalpies | B37: -968.22611
A38: Sum of electronic and thermal Free Energies | B38: -968.29197
A41: MP2_C2_NC3-CH3_corr-OH_up.out
A42: SCF Done: E(RHF) | B42: -965.251326539 A.U. after 1 cycles
A43: Zero-point correction | B43: 0.269959 (Hartree/Particle)
A44: Thermal correction to Energy | B44: 0.288231
A45: Thermal correction to Enthalpy | B45: 0.289175
A46: Thermal correction to Gibbs Free Energy | B46: 0.223445
A47: Sum of electronic and zero-point Energies | B47: -968.26111
...

Sheet SMD
A1: from:
A2: /home/c.sacal5/Scratch/Mech_monomers/proton_site/corrected/solv/SMD
E4: =A5 -> smd_C2_NC3-CH3_corr-C2H-ON.out | F4: =B14 -> -970.2555
A5: smd_C2_NC3-CH3_corr-C2H-ON.out | E5: =A17 -> smd_C2_NC3-CH3_corr-Hcap.out | F5: =B26 -> -970.27236
A6: SCF Done: E(RwB97XD) | B6: -970.484802713 A.U. after 1 cycles | E6: =A29 -> smd_C2_NC3-CH3_corr-OH_down.out | F6: =B38 -> -970.25294
A7: Zero-point correction | B7: 0.271668 (Hartree/Particle) | E7: =A41 -> smd_C2_NC3-CH3_corr-OH_up.out | F7: =B50 -> -970.25086
A8: Thermal correction to Energy | B8: 0.286883 | E8: =A53 -> smd_C2_NC3-CH3_corr_HI.out | F8: =B62 -> -969.8757
A9: Thermal correction to Enthalpy | B9: 0.287827
A10: Thermal correction to Gibbs Free Energy | B10: 0.229301
A11: Sum of electronic and zero-point Energies | B11: -970.21313
A12: Sum of electronic and thermal Energies | B12: -970.19792
A13: Sum of electronic and thermal Enthalpies | B13: -970.19698
A14: Sum of electronic and thermal Free Energies | B14: -970.2555
A17: smd_C2_NC3-CH3_corr-Hcap.out
A18: SCF Done: E(RwB97XD) | B18: -970.495743558 A.U. after 1 cycles
A19: Zero-point correction | B19: 0.266352 (Hartree/Particle)
A20: Thermal correction to Energy | B20: 0.282495
A21: Thermal correction to Enthalpy | B21: 0.283439
A22: Thermal correction to Gibbs Free Energy | B22: 0.223384
A23: Sum of electronic and zero-point Energies | B23: -970.22939
A24: Sum of electronic and thermal Energies | B24: -970.21325
A25: Sum of electronic and thermal Enthalpies | B25: -970.21231
A26: Sum of electronic and thermal Free Energies | B26: -970.27236
A29: smd_C2_NC3-CH3_corr-OH_down.out
A30: SCF Done: E(RwB97XD) | B30: -970.477926669 A.U. after 1 cycles
A31: Zero-point correction | B31: 0.267625 (Hartree/Particle)
A32: Thermal correction to Energy | B32: 0.283113
A33: Thermal correction to Enthalpy | B33: 0.284058
A34: Thermal correction to Gibbs Free Energy | B34: 0.224989
A35: Sum of electronic and zero-point Energies | B35: -970.2103
A36: Sum of electronic and thermal Energies | B36: -970.19481
A37: Sum of electronic and thermal Enthalpies | B37: -970.19387
A38: Sum of electronic and thermal Free Energies | B38: -970.25294
A41: smd_C2_NC3-CH3_corr-OH_up.out
A42: SCF Done: E(RwB97XD) | B42: -970.473981892 A.U. after 1 cycles
A43: Zero-point correction | B43: 0.266138 (Hartree/Particle)
A44: Thermal correction to Energy | B44: 0.281986
A45: Thermal correction to Enthalpy | B45: 0.28293
A46: Thermal correction to Gibbs Free Energy | B46: 0.223124
A47: Sum of electronic and zero-point Energies | B47: -970.20784
...
